Workbook

Sheet Planificación
A1: Figura: “Planificación acumulada de tareas — Incrementos 1, 2 y 3”
A2: Sprint 1 · 27-07-2026 a 16-08-2026 (Incremento 1, morado) · Sprint 2 · 24-08-2026 a 13-09-2026 (Incremento 2, azul) · Sprint 3 · 15-09-2026 a 03-10-2026 (Incremento 3, verde)
A4: ID Tarea | B4: Descripción de Tarea | C4: Responsable | D4: Incremento | E4: HH Est. | F4: Inicio | G4: Fin | H4: HH Real | I4: Estado
A5: SPRINT 1 · INCREMENTO 1 — trabajo heredado (29 tareas)
A6: TA 1 — Levantamiento y análisis
A7: S1-001 | B7: TA 1.1 – Levantando los requerimientos con la contraparte de Constructora M5 | C7: Alexander Hanke | D7: Incremento 1 | E7: 6 | F7: 27-07-2026 | G7: 28-07-2026 | H7: 6 | I7: Finalizado
A8: S1-002 | B8: TA 1.2 – Redactando el Documento 0 con los requerimientos y los casos de uso | C8: Roberto Seguel | D8: Incremento 1 | E8: 8 | F8: 27-07-2026 | G8: 30-07-2026 | H8: 10 | I8: Finalizado
A9: S1-003 | B9: TA 1.3 – Construyendo la matriz de trazabilidad entre RF, CU y UR | C9: Roberto Seguel | D9: Incremento 1 | E9: 6 | F9: 29-07-2026 | G9: 31-07-2026 | H9: 6 | I9: Finalizado
A10: S1-004 | B10: TA 1.4 – Definiendo la distribución de los cuatro incrementos del proyecto | C10: Alexander Hanke | D10: Incremento 1 | E10: 4 | F10: 28-07-2026 | G10: 29-07-2026 | H10: 4 | I10: Finalizado
A11: TA 2 — Arquitectura y base del proyecto
A12: S1-005 | B12: TA 2.1 – Creando el proyecto Django y la estructura de aplicaciones | C12: Alexander Hanke | D12: Incremento 1 | E12: 6 | F12: 29-07-2026 | G12: 31-07-2026 | H12: 6 | I12: Finalizado
A13: S1-006 | B13: TA 2.2 – Instalando y configurando PostgreSQL en el equipo de desarrollo | C13: Josué Barrera | D13: Incremento 1 | E13: 6 | F13: 29-07-2026 | G13: 30-07-2026 | H13: 4 | I13: Finalizado
A14: S1-007 | B14: TA 2.3 – Definiendo el patrón MVC++ y la convención de nombres de vistas y controladores | C14: Alexander Hanke | D14: Incremento 1 | E14: 4 | F14: 30-07-2026 | G14: 31-07-2026 | H14: 4 | I14: Finalizado
A15: S1-008 | B15: TA 2.4 – Integrando Bootstrap 5 y la plantilla base del sistema | C15: Josué Barrera | D15: Incremento 1 | E15: 6 | F15: 30-07-2026 | G15: 01-08-2026 | H15: 6 | I15: Finalizado
A16: TA 3 — Desarrollo del incremento
A17: S1-009 | B17: TA 3.1 – Implementando el modelo de usuarios con roles del sistema | C17: Alexander Hanke | D17: Incremento 1 | E17: 6 | F17: 31-07-2026 | G17: 02-08-2026 | H17: 6 | I17: Finalizado
A18: S1-010 | B18: TA 3.2 – Implementando el inicio y el cierre de sesión | C18: Josué Barrera | D18: Incremento 1 | E18: 6 | F18: 01-08-2026 | G18: 03-08-2026 | H18: 6 | I18: Finalizado
A19: S1-011 | B19: TA 3.3 – Implementando la creación y la edición de cuentas de usuario | C19: Alexander Hanke | D19: Incremento 1 | E19: 6 | F19: 02-08-2026 | G19: 04-08-2026 | H19: 6 | I19: Finalizado
A20: S1-012 | B20: TA 3.4 – Implementando la deshabilitación de cuentas y el control de acceso por rol | C20: Josué Barrera | D20: Incremento 1 | E20: 4 | F20: 03-08-2026 | G20: 05-08-2026 | H20: 6 | I20: Finalizado
A21: S1-013 | B21: TA 3.5 – Implementando el registro y la edición de proveedores | C21: Alexander Hanke | D21: Incremento 1 | E21: 6 | F21: 04-08-2026 | G21: 06-08-2026 | H21: 6 | I21: Finalizado
A22: S1-014 | B22: TA 3.6 – Implementando la asignación del jefe de proyecto | C22: Josué Barrera | D22: Incremento 1 | E22: 6 | F22: 05-08-2026 | G22: 07-08-2026 | H22: 6 | I22: Finalizado
A23: S1-015 | B23: TA 3.7 – Implementando el cambio de estado del proyecto | C23: Alexander Hanke | D23: Incremento 1 | E23: 6 | F23: 06-08-2026 | G23: 08-08-2026 | H23: 6 | I23: Finalizado
A24: S1-016 | B24: TA 3.8 – Implementando la creación de la solicitud de materiales | C24: Josué Barrera | D24: Incremento 1 | E24: 4 | F24: 07-08-2026 | G24: 09-08-2026 | H24: 6 | I24: Finalizado
A25: S1-017 | B25: TA 3.9 – Implementando el detalle y la edición de la solicitud de materiales | C25: Alexander Hanke | D25: Incremento 1 | E25: 6 | F25: 08-08-2026 | G25: 10-08-2026 | H25: 6 | I25: Finalizado
A26: S1-018 | B26: TA 3.10 – Implementando la consulta y el seguimiento de solicitudes | C26: Josué Barrera | D26: Incremento 1 | E26: 6 | F26: 09-08-2026 | G26: 11-08-2026 | H26: 6 | I26: Finalizado
A27: S1-019 | B27: TA 3.11 – Implementando el panel principal con el menú según el rol | C27: Alexander Hanke | D27: Incremento 1 | E27: 6 | F27: 10-08-2026 | G27: 12-08-2026 | H27: 6 | I27: Finalizado
A28: S1-020 | B28: TA 3.12 – Cargando los datos de prueba iniciales en la base de datos | C28: Josué Barrera | D28: Incremento 1 | E28: 6 | F28: 11-08-2026 | G28: 12-08-2026 | H28: 4 | I28: Finalizado
A29: TA 4 — Modelado y documentación
A30: S1-021 | B30: TA 4.1 – Realizando el modelo entidad-relación del incremento | C30: Roberto Seguel | D30: Incremento 1 | E30: 6 | F30: 01-08-2026 | G30: 03-08-2026 | H30: 6 | I30: Finalizado
A31: S1-022 | B31: TA 4.2 – Realizando el diagrama de casos de uso del sistema | C31: Roberto Seguel | D31: Incremento 1 | E31: 4 | F31: 03-08-2026 | G31: 04-08-2026 | H31: 4 | I31: Finalizado
A32: S1-023 | B32: TA 4.3 – Realizando los diagramas de secuencia del incremento | C32: Roberto Seguel | D32: Incremento 1 | E32: 6 | F32: 05-08-2026 | G32: 09-08-2026 | H32: 8 | I32: Finalizado
A33: S1-024 | B33: TA 4.4 – Realizando el diagrama de despliegue inicial | C33: Roberto Seguel | D33: Incremento 1 | E33: 4 | F33: 09-08-2026 | G33: 10-08-2026 | H33: 4 | I33: Finalizado
A34: S1-025 | B34: TA 4.5 – Redactando el informe del Incremento 1 | C34: Roberto Seguel | D34: Incremento 1 | E34: 6 | F34: 10-08-2026 | G34: 14-08-2026 | H34: 8 | I34: Finalizado
A35: S1-026 | B35: TA 4.6 – Construyendo la tabla de esfuerzo y las gráficas del sprint | C35: Roberto Seguel | D35: Incremento 1 | E35: 4 | F35: 13-08-2026 | G35: 14-08-2026 | H35: 4 | I35: Finalizado
A36: TA 5 — Pruebas y verificación
A37: S1-027 | B37: TA 5.1 – Ejecutando las pruebas de caja negra de los casos de uso del incremento | C37: Josué Barrera | D37: Incremento 1 | E37: 6 | F37: 12-08-2026 | G37: 14-08-2026 | H37: 6 | I37: Finalizado
A38: S1-028 | B38: TA 5.2 – Documentando los casos de prueba y su evidencia | C38: Roberto Seguel | D38: Incremento 1 | E38: 4 | F38: 13-08-2026 | G38: 15-08-2026 | H38: 4 | I38: Finalizado
A39: S1-029 | B39: TA 5.3 – Corrigiendo los hallazgos levantados en las pruebas | C39: Josué Barrera | D39: Incremento 1 | E39: 4 | F39: 14-08-2026 | G39: 16-08-2026 | H39: 4 | I39: Finalizado
A40: Subtotal Sprint 1 · Incremento 1 | E40: =SUM(E7:E39) | H40: =SUM(H7:H39)
A42: SPRINT 2 · INCREMENTO 2 — trabajo nuevo (52 tareas)
...

Sheet Gráficas Incremento 2
A1: Gráficas de seguimiento — Gráficas Incremento 2
A2: Burn-Down y Burn-Up del Sprint 2. Los datos salen de la fila «Horas pendientes del Sprint 2» de la tabla de esfuerzo.
A4: Día | B4: Fecha | C4: Pendiente real (HH) | D4: Pendiente planificado (HH) | E4: Acumulado real (HH) | F4: Acumulado planificado (HH) | G4: Alcance comprometido (HH)
A5: 0 | B5: Inicio | C5: ='Tabla de Esfuerzo'!$H$8 | D5: ='Tabla de Esfuerzo'!$H$8 | E5: 0 | F5: 0 | G5: ='Tabla de Esfuerzo'!$H$8
A6: 1 | B6: 24-08 | C6: ='Tabla de Esfuerzo'!Z8 | D6: =ROUND('Tabla de Esfuerzo'!$H$8*(1-A6/21),0) | E6: ='Tabla de Esfuerzo'!$H$8-C6 | F6: ='Tabla de Esfuerzo'!$H$8-D6 | G6: ='Tabla de Esfuerzo'!$H$8
A7: 2 | B7: 25-08 | C7: ='Tabla de Esfuerzo'!AA8 | D7: =ROUND('Tabla de Esfuerzo'!$H$8*(1-A7/21),0) | E7: ='Tabla de Esfuerzo'!$H$8-C7 | F7: ='Tabla de Esfuerzo'!$H$8-D7 | G7: ='Tabla de Esfuerzo'!$H$8
A8: 3 | B8: 26-08 | C8: ='Tabla de Esfuerzo'!AB8 | D8: =ROUND('Tabla de Esfuerzo'!$H$8*(1-A8/21),0) | E8: ='Tabla de Esfuerzo'!$H$8-C8 | F8: ='Tabla de Esfuerzo'!$H$8-D8 | G8: ='Tabla de Esfuerzo'!$H$8
A9: 4 | B9: 27-08 | C9: ='Tabla de Esfuerzo'!AC8 | D9: =ROUND('Tabla de Esfuerzo'!$H$8*(1-A9/21),0) | E9: ='Tabla de Esfuerzo'!$H$8-C9 | F9: ='Tabla de Esfuerzo'!$H$8-D9 | G9: ='Tabla de Esfuerzo'!$H$8
A10: 5 | B10: 28-08 | C10: ='Tabla de Esfuerzo'!AD8 | D10: =ROUND('Tabla de Esfuerzo'!$H$8*(1-A10/21),0) | E10: ='Tabla de Esfuerzo'!$H$8-C10 | F10: ='Tabla de Esfuerzo'!$H$8-D10 | G10: ='Tabla de Esfuerzo'!$H$8
A11: 6 | B11: 29-08 | C11: ='Tabla de Esfuerzo'!AE8 | D11: =ROUND('Tabla de Esfuerzo'!$H$8*(1-A11/21),0) | E11: ='Tabla de Esfuerzo'!$H$8-C11 | F11: ='Tabla de Esfuerzo'!$H$8-D11 | G11: ='Tabla de Esfuerzo'!$H$8
A12: 7 | B12: 30-08 | C12: ='Tabla de Esfuerzo'!AF8 | D12: =ROUND('Tabla de Esfuerzo'!$H$8*(1-A12/21),0) | E12: ='Tabla de Esfuerzo'!$H$8-C12 | F12: ='Tabla de Esfuerzo'!$H$8-D12 | G12: ='Tabla de Esfuerzo'!$H$8
A13: 8 | B13: 31-08 | C13: ='Tabla de Esfuerzo'!AG8 | D13: =ROUND('Tabla de Esfuerzo'!$H$8*(1-A13/21),0) | E13: ='Tabla de Esfuerzo'!$H$8-C13 | F13: ='Tabla de Esfuerzo'!$H$8-D13 | G13: ='Tabla de Esfuerzo'!$H$8
A14: 9 | B14: 01-09 | C14: ='Tabla de Esfuerzo'!AH8 | D14: =ROUND('Tabla de Esfuerzo'!$H$8*(1-A14/21),0) | E14: ='Tabla de Esfuerzo'!$H$8-C14 | F14: ='Tabla de Esfuerzo'!$H$8-D14 | G14: ='Tabla de Esfuerzo'!$H$8
A15: 10 | B15: 02-09 | C15: ='Tabla de Esfuerzo'!AI8 | D15: =ROUND('Tabla de Esfuerzo'!$H$8*(1-A15/21),0) | E15: ='Tabla de Esfuerzo'!$H$8-C15 | F15: ='Tabla de Esfuerzo'!$H$8-D15 | G15: ='Tabla de Esfuerzo'!$H$8
A16: 11 | B16: 03-09 | C16: ='Tabla de Esfuerzo'!AJ8 | D16: =ROUND('Tabla de Esfuerzo'!$H$8*(1-A16/21),0) | E16: ='Tabla de Esfuerzo'!$H$8-C16 | F16: ='Tabla de Esfuerzo'!$H$8-D16 | G16: ='Tabla de Esfuerzo'!$H$8
A17: 12 | B17: 04-09 | C17: ='Tabla de Esfuerzo'!AK8 | D17: =ROUND('Tabla de Esfuerzo'!$H$8*(1-A17/21),0) | E17: ='Tabla de Esfuerzo'!$H$8-C17 | F17: ='Tabla de Esfuerzo'!$H$8-D17 | G17: ='Tabla de Esfuerzo'!$H$8
A18: 13 | B18: 05-09 | C18: ='Tabla de Esfuerzo'!AL8 | D18: =ROUND('Tabla de Esfuerzo'!$H$8*(1-A18/21),0) | E18: ='Tabla de Esfuerzo'!$H$8-C18 | F18: ='Tabla de Esfuerzo'!$H$8-D18 | G18: ='Tabla de Esfuerzo'!$H$8
A19: 14 | B19: 06-09 | C19: ='Tabla de Esfuerzo'!AM8 | D19: =ROUND('Tabla de Esfuerzo'!$H$8*(1-A19/21),0) | E19: ='Tabla de Esfuerzo'!$H$8-C19 | F19: ='Tabla de Esfuerzo'!$H$8-D19 | G19: ='Tabla de Esfuerzo'!$H$8
A20: 15 | B20: 07-09 | C20: ='Tabla de Esfuerzo'!AN8 | D20: =ROUND('Tabla de Esfuerzo'!$H$8*(1-A20/21),0) | E20: ='Tabla de Esfuerzo'!$H$8-C20 | F20: ='Tabla de Esfuerzo'!$H$8-D20 | G20: ='Tabla de Esfuerzo'!$H$8
A21: 16 | B21: 08-09 | C21: ='Tabla de Esfuerzo'!AO8 | D21: =ROUND('Tabla de Esfuerzo'!$H$8*(1-A21/21),0) | E21: ='Tabla de Esfuerzo'!$H$8-C21 | F21: ='Tabla de Esfuerzo'!$H$8-D21 | G21: ='Tabla de Esfuerzo'!$H$8
A22: 17 | B22: 09-09 | C22: ='Tabla de Esfuerzo'!AP8 | D22: =ROUND('Tabla de Esfuerzo'!$H$8*(1-A22/21),0) | E22: ='Tabla de Esfuerzo'!$H$8-C22 | F22: ='Tabla de Esfuerzo'!$H$8-D22 | G22: ='Tabla de Esfuerzo'!$H$8
A23: 18 | B23: 10-09 | C23: ='Tabla de Esfuerzo'!AQ8 | D23: =ROUND('Tabla de Esfuerzo'!$H$8*(1-A23/21),0) | E23: ='Tabla de Esfuerzo'!$H$8-C23 | F23: ='Tabla de Esfuerzo'!$H$8-D23 | G23: ='Tabla de Esfuerzo'!$H$8
A24: 19 | B24: 11-09 | C24: ='Tabla de Esfuerzo'!AR8 | D24: =ROUND('Tabla de Esfuerzo'!$H$8*(1-A24/21),0) | E24: ='Tabla de Esfuerzo'!$H$8-C24 | F24: ='Tabla de Esfuerzo'!$H$8-D24 | G24: ='Tabla de Esfuerzo'!$H$8
A25: 20 | B25: 12-09 | C25: ='Tabla de Esfuerzo'!AS8 | D25: =ROUND('Tabla de Esfuerzo'!$H$8*(1-A25/21),0) | E25: ='Tabla de Esfuerzo'!$H$8-C25 | F25: ='Tabla de Esfuerzo'!$H$8-D25 | G25: ='Tabla de Esfuerzo'!$H$8
A26: 21 | B26: 13-09 | C26: ='Tabla de Esfuerzo'!AT8 | D26: =ROUND('Tabla de Esfuerzo'!$H$8*(1-A26/21),0) | E26: ='Tabla de Esfuerzo'!$H$8-C26 | F26: ='Tabla de Esfuerzo'!$H$8-D26 | G26: ='Tabla de Esfuerzo'!$H$8

Sheet Gráficas Incremento 3
A1: Gráficas de seguimiento — Gráficas Incremento 3
A2: Burn-Down y Burn-Up del Sprint 3. Los datos salen de la fila «Horas pendientes del Sprint 3» de la tabla de esfuerzo.
A4: Día | B4: Fecha | C4: Pendiente real (HH) | D4: Pendiente planificado (HH) | E4: Acumulado real (HH) | F4: Acumulado planificado (HH) | G4: Alcance comprometido (HH)
A5: 0 | B5: Inicio | C5: ='Tabla de Esfuerzo'!$E$9 | D5: =Planificación!$E$131 | E5: 0 | F5: =Planificación!$E$131-D5 | G5: ='Tabla de Esfuerzo'!$E$9
A6: 1 | B6: 15-09 | C6: ='Tabla de Esfuerzo'!AU9 | D6: =ROUND(Planificación!$E$131*(1-A6/19),0) | E6: ='Tabla de Esfuerzo'!$E$9-C6 | F6: =Planificación!$E$131-D6 | G6: ='Tabla de Esfuerzo'!$E$9
A7: 2 | B7: 16-09 | C7: ='Tabla de Esfuerzo'!AV9 | D7: =ROUND(Planificación!$E$131*(1-A7/19),0) | E7: ='Tabla de Esfuerzo'!$E$9-C7 | F7: =Planificación!$E$131-D7 | G7: ='Tabla de Esfuerzo'!$E$9
A8: 3 | B8: 17-09 | C8: ='Tabla de Esfuerzo'!AW9 | D8: =ROUND(Planificación!$E$131*(1-A8/19),0) | E8: ='Tabla de Esfuerzo'!$E$9-C8 | F8: =Planificación!$E$131-D8 | G8: ='Tabla de Esfuerzo'!$E$9
A9: 4 | B9: 18-09 | C9: ='Tabla de Esfuerzo'!AX9 | D9: =ROUND(Planificación!$E$131*(1-A9/19),0) | E9: ='Tabla de Esfuerzo'!$E$9-C9 | F9: =Planificación!$E$131-D9 | G9: ='Tabla de Esfuerzo'!$E$9
A10: 5 | B10: 19-09 | C10: ='Tabla de Esfuerzo'!AY9 | D10: =ROUND(Planificación!$E$131*(1-A10/19),0) | E10: ='Tabla de Esfuerzo'!$E$9-C10 | F10: =Planificación!$E$131-D10 | G10: ='Tabla de Esfuerzo'!$E$9
A11: 6 | B11: 20-09 | C11: ='Tabla de Esfuerzo'!AZ9 | D11: =ROUND(Planificación!$E$131*(1-A11/19),0) | E11: ='Tabla de Esfuerzo'!$E$9-C11 | F11: =Planificación!$E$131-D11 | G11: ='Tabla de Esfuerzo'!$E$9
A12: 7 | B12: 21-09 | C12: ='Tabla de Esfuerzo'!BA9 | D12: =ROUND(Planificación!$E$131*(1-A12/19),0) | E12: ='Tabla de Esfuerzo'!$E$9-C12 | F12: =Planificación!$E$131-D12 | G12: ='Tabla de Esfuerzo'!$E$9
A13: 8 | B13: 22-09 | C13: ='Tabla de Esfuerzo'!BB9 | D13: =ROUND(Planificación!$E$131*(1-A13/19),0) | E13: ='Tabla de Esfuerzo'!$E$9-C13 | F13: =Planificación!$E$131-D13 | G13: ='Tabla de Esfuerzo'!$E$9
A14: 9 | B14: 23-09 | C14: ='Tabla de Esfuerzo'!BC9 | D14: =ROUND(Planificación!$E$131*(1-A14/19),0) | E14: ='Tabla de Esfuerzo'!$E$9-C14 | F14: =Planificación!$E$131-D14 | G14: ='Tabla de Esfuerzo'!$E$9
A15: 10 | B15: 24-09 | C15: ='Tabla de Esfuerzo'!BD9 | D15: =ROUND(Planificación!$E$131*(1-A15/19),0) | E15: ='Tabla de Esfuerzo'!$E$9-C15 | F15: =Planificación!$E$131-D15 | G15: ='Tabla de Esfuerzo'!$E$9
A16: 11 | B16: 25-09 | C16: ='Tabla de Esfuerzo'!BE9 | D16: =ROUND(Planificación!$E$131*(1-A16/19),0) | E16: ='Tabla de Esfuerzo'!$E$9-C16 | F16: =Planificación!$E$131-D16 | G16: ='Tabla de Esfuerzo'!$E$9
A17: 12 | B17: 26-09 | C17: ='Tabla de Esfuerzo'!BF9 | D17: =ROUND(Planificación!$E$131*(1-A17/19),0) | E17: ='Tabla de Esfuerzo'!$E$9-C17 | F17: =Planificación!$E$131-D17 | G17: ='Tabla de Esfuerzo'!$E$9
A18: 13 | B18: 27-09 | C18: ='Tabla de Esfuerzo'!BG9 | D18: =ROUND(Planificación!$E$131*(1-A18/19),0) | E18: ='Tabla de Esfuerzo'!$E$9-C18 | F18: =Planificación!$E$131-D18 | G18: ='Tabla de Esfuerzo'!$E$9
A19: 14 | B19: 28-09 | C19: ='Tabla de Esfuerzo'!BH9 | D19: =ROUND(Planificación!$E$131*(1-A19/19),0) | E19: ='Tabla de Esfuerzo'!$E$9-C19 | F19: =Planificación!$E$131-D19 | G19: ='Tabla de Esfuerzo'!$E$9
A20: 15 | B20: 29-09 | C20: ='Tabla de Esfuerzo'!BI9 | D20: =ROUND(Planificación!$E$131*(1-A20/19),0) | E20: ='Tabla de Esfuerzo'!$E$9-C20 | F20: =Planificación!$E$131-D20 | G20: ='Tabla de Esfuerzo'!$E$9
A21: 16 | B21: 30-09 | C21: ='Tabla de Esfuerzo'!BJ9 | D21: =ROUND(Planificación!$E$131*(1-A21/19),0) | E21: ='Tabla de Esfuerzo'!$E$9-C21 | F21: =Planificación!$E$131-D21 | G21: ='Tabla de Esfuerzo'!$E$9
A22: 17 | B22: 01-10 | C22: ='Tabla de Esfuerzo'!BK9 | D22: =ROUND(Planificación!$E$131*(1-A22/19),0) | E22: ='Tabla de Esfuerzo'!$E$9-C22 | F22: =Planificación!$E$131-D22 | G22: ='Tabla de Esfuerzo'!$E$9
A23: 18 | B23: 02-10 | C23: ='Tabla de Esfuerzo'!BL9 | D23: =ROUND(Planificación!$E$131*(1-A23/19),0) | E23: ='Tabla de Esfuerzo'!$E$9-C23 | F23: =Planificación!$E$131-D23 | G23: ='Tabla de Esfuerzo'!$E$9
A24: 19 | B24: 03-10 | C24: ='Tabla de Esfuerzo'!BM9 | D24: =ROUND(Planificación!$E$131*(1-A24/19),0) | E24: ='Tabla de Esfuerzo'!$E$9-C24 | F24: =Planificación!$E$131-D24 | G24: ='Tabla de Esfuerzo'!$E$9

Sheet Tabla de Esfuerzo
A1: Tabla: “Tabla de esfuerzo acumulada de los Incrementos 1, 2 y 3”
A2: 61 días de sprint: 21 del Sprint 1 (morado), 21 del Sprint 2 (azul) y 19 del Sprint 3 (verde). Cada celda son las horas-hombre que quedaban pendientes de esa tarea ese día.
A4: Tarea | B4: Responsable | C4: Incremento | D4: HH | E4: 27-07 | F4: 28-07 | G4: 29-07 | H4: 30-07 | I4: 31-07 | J4: 01-08 | K4: 02-08 | L4: 03-08 | M4: 04-08 | N4: 05-08 | O4: 06-08 | P4: 07-08 | Q4: 08-08 | R4: 09-08 | S4: 10-08 | T4: 11-08 | U4: 12-08 | V4: 13-08 | W4: 14-08 | X4: 15-08 | Y4: 16-08 | Z4: 24-08 | AA4: 25-08 | AB4: 26-08 | AC4: 27-08 | AD4: 28-08 | AE4: 29-08 | AF4: 30-08 | AG4: 31-08 | AH4: 01-09 | AI4: 02-09 | AJ4: 03-09 | AK4: 04-09 | AL4: 05-09 | AM4: 06-09 | AN4: 07-09 | AO4: 08-09 | AP4: 09-09 | AQ4: 10-09 | AR4: 11-09 | AS4: 12-09 | AT4: 13-09 | AU4: 15-09 | AV4: 16-09 | AW4: 17-09 | AX4: 18-09 | AY4: 19-09 | AZ4: 20-09 | BA4: 21-09 | BB4: 22-09 | BC4: 23-09 | BD4: 24-09 | BE4: 25-09 | BF4: 26-09 | BG4: 27-09 | BH4: 28-09 | BI4: 29-09 | BJ4: 30-09 | BK4: 01-10 | BL4: 02-10 | BM4: 03-10
A5: Tareas pendientes | E5: =COUNTIF(E11:E39,">0")+COUNTIF(E41:E92,">0")+COUNTIF(E95:E127,">0") | F5: =COUNTIF(F11:F39,">0")+COUNTIF(F41:F92,">0")+COUNTIF(F95:F127,">0") | G5: =COUNTIF(G11:G39,">0")+COUNTIF(G41:G92,">0")+COUNTIF(G95:G127,">0") | H5: =COUNTIF(H11:H39,">0")+COUNTIF(H41:H92,">0")+COUNTIF(H95:H127,">0") | I5: =COUNTIF(I11:I39,">0")+COUNTIF(I41:I92,">0")+COUNTIF(I95:I127,">0") | J5: =COUNTIF(J11:J39,">0")+COUNTIF(J41:J92,">0")+COUNTIF(J95:J127,">0") | K5: =COUNTIF(K11:K39,">0")+COUNTIF(K41:K92,">0")+COUNTIF(K95:K127,">0") | L5: =COUNTIF(L11:L39,">0")+COUNTIF(L41:L92,">0")+COUNTIF(L95:L127,">0") | ... BM5: =COUNTIF(BM11:BM39,">0")+COUNTIF(BM41:BM92,">0")+COUNTIF(BM95:BM127,">0")
A6: Horas pendientes acumuladas | E6: =SUM(E11:E39)+SUM(E41:E92)+SUM(E95:E127) | F6: =SUM(F11:F39)+SUM(F41:F92)+SUM(F95:F127) | G6: =SUM(G11:G39)+SUM(G41:G92)+SUM(G95:G127) | H6: =SUM(H11:H39)+SUM(H41:H92)+SUM(H95:H127) | I6: =SUM(I11:I39)+SUM(I41:I92)+SUM(I95:I127) | J6: =SUM(J11:J39)+SUM(J41:J92)+SUM(J95:J127) | K6: =SUM(K11:K39)+SUM(K41:K92)+SUM(K95:K127) | L6: =SUM(L11:L39)+SUM(L41:L92)+SUM(L95:L127) | ... BM6: =SUM(BM11:BM39)+SUM(BM41:BM92)+SUM(BM95:BM127)
A7: Horas pendientes del Sprint 1 | E7: =SUM(E11:E39) | F7: =SUM(F11:F39) | G7: =SUM(G11:G39) | H7: =SUM(H11:H39) | I7: =SUM(I11:I39) | J7: =SUM(J11:J39) | K7: =SUM(K11:K39) | L7: =SUM(L11:L39) | ... BM7: =SUM(BM11:BM39)
A8: Horas pendientes del Sprint 2 | E8: =SUM(E41:E92) | F8: =SUM(F41:F92) | G8: =SUM(G41:G92) | H8: =SUM(H41:H92) | I8: =SUM(I41:I92) | J8: =SUM(J41:J92) | K8: =SUM(K41:K92) | L8: =SUM(L41:L92) | ... BM8: =SUM(BM41:BM92)
A9: Horas pendientes del Sprint 3 | E9: =SUM(E95:E127) | F9: =SUM(F95:F127) | G9: =SUM(G95:G127) | H9: =SUM(H95:H127) | I9: =SUM(I95:I127) | J9: =SUM(J95:J127) | K9: =SUM(K95:K127) | L9: =SUM(L95:L127) | ... BM9: =SUM(BM95:BM127)
A10: SPRINT 1 · INCREMENTO 1 (29 tareas)
A11: TA 1.1 – Levantando los requerimientos con la contraparte de Constructora M5 | B11: Alexander Hanke | C11: Incremento 1 | D11: =Planificación!H7 | E11: 3 | F11: 0 | G11: 0 | H11: 0 | I11: 0 | J11: 0 | K11: 0 | L11: 0 | M11: 0 | N11: 0 | O11: 0 | P11: 0 | Q11: 0 | R11: 0 | S11: 0 | T11: 0 | U11: 0 | V11: 0 | W11: 0 | X11: 0 | Y11: 0 | Z11: 0 | AA11: 0 | AB11: 0 | AC11: 0 | AD11: 0 | AE11: 0 | AF11: 0 | AG11: 0 | AH11: 0 | AI11: 0 | AJ11: 0 | AK11: 0 | AL11: 0 | AM11: 0 | AN11: 0 | AO11: 0 | AP11: 0 | AQ11: 0 | AR11: 0 | AS11: 0 | AT11: 0
A12: TA 1.2 – Redactando el Documento 0 con los requerimientos y los casos de uso | B12: Roberto Seguel | C12: Incremento 1 | D12: =Planificación!H8 | E12: 8 | F12: 5 | G12: 2 | H12: 0 | I12: 0 | J12: 0 | K12: 0 | L12: 0 | M12: 0 | N12: 0 | O12: 0 | P12: 0 | Q12: 0 | R12: 0 | S12: 0 | T12: 0 | U12: 0 | V12: 0 | W12: 0 | X12: 0 | Y12: 0 | Z12: 0 | AA12: 0 | AB12: 0 | AC12: 0 | AD12: 0 | AE12: 0 | AF12: 0 | AG12: 0 | AH12: 0 | AI12: 0 | AJ12: 0 | AK12: 0 | AL12: 0 | AM12: 0 | AN12: 0 | AO12: 0 | AP12: 0 | AQ12: 0 | AR12: 0 | AS12: 0 | AT12: 0
A13: TA 1.3 – Construyendo la matriz de trazabilidad entre RF, CU y UR | B13: Roberto Seguel | C13: Incremento 1 | D13: =Planificación!H9 | E13: 6 | F13: 6 | G13: 4 | H13: 2 | I13: 0 | J13: 0 | K13: 0 | L13: 0 | M13: 0 | N13: 0 | O13: 0 | P13: 0 | Q13: 0 | R13: 0 | S13: 0 | T13: 0 | U13: 0 | V13: 0 | W13: 0 | X13: 0 | Y13: 0 | Z13: 0 | AA13: 0 | AB13: 0 | AC13: 0 | AD13: 0 | AE13: 0 | AF13: 0 | AG13: 0 | AH13: 0 | AI13: 0 | AJ13: 0 | AK13: 0 | AL13: 0 | AM13: 0 | AN13: 0 | AO13: 0 | AP13: 0 | AQ13: 0 | AR13: 0 | AS13: 0 | AT13: 0
A14: TA 1.4 – Definiendo la distribución de los cuatro incrementos del proyecto | B14: Alexander Hanke | C14: Incremento 1 | D14: =Planificación!H10 | E14: 4 | F14: 2 | G14: 0 | H14: 0 | I14: 0 | J14: 0 | K14: 0 | L14: 0 | M14: 0 | N14: 0 | O14: 0 | P14: 0 | Q14: 0 | R14: 0 | S14: 0 | T14: 0 | U14: 0 | V14: 0 | W14: 0 | X14: 0 | Y14: 0 | Z14: 0 | AA14: 0 | AB14: 0 | AC14: 0 | AD14: 0 | AE14: 0 | AF14: 0 | AG14: 0 | AH14: 0 | AI14: 0 | AJ14: 0 | AK14: 0 | AL14: 0 | AM14: 0 | AN14: 0 | AO14: 0 | AP14: 0 | AQ14: 0 | AR14: 0 | AS14: 0 | AT14: 0
A15: TA 2.1 – Creando el proyecto Django y la estructura de aplicaciones | B15: Alexander Hanke | C15: Incremento 1 | D15: =Planificación!H12 | E15: 6 | F15: 6 | G15: 4 | H15: 2 | I15: 0 | J15: 0 | K15: 0 | L15: 0 | M15: 0 | N15: 0 | O15: 0 | P15: 0 | Q15: 0 | R15: 0 | S15: 0 | T15: 0 | U15: 0 | V15: 0 | W15: 0 | X15: 0 | Y15: 0 | Z15: 0 | AA15: 0 | AB15: 0 | AC15: 0 | AD15: 0 | AE15: 0 | AF15: 0 | AG15: 0 | AH15: 0 | AI15: 0 | AJ15: 0 | AK15: 0 | AL15: 0 | AM15: 0 | AN15: 0 | AO15: 0 | AP15: 0 | AQ15: 0 | AR15: 0 | AS15: 0 | AT15: 0
A16: TA 2.2 – Instalando y configurando PostgreSQL en el equipo de desarrollo | B16: Josué Barrera | C16: Incremento 1 | D16: =Planificación!H13 | E16: 4 | F16: 4 | G16: 2 | H16: 0 | I16: 0 | J16: 0 | K16: 0 | L16: 0 | M16: 0 | N16: 0 | O16: 0 | P16: 0 | Q16: 0 | R16: 0 | S16: 0 | T16: 0 | U16: 0 | V16: 0 | W16: 0 | X16: 0 | Y16: 0 | Z16: 0 | AA16: 0 | AB16: 0 | AC16: 0 | AD16: 0 | AE16: 0 | AF16: 0 | AG16: 0 | AH16: 0 | AI16: 0 | AJ16: 0 | AK16: 0 | AL16: 0 | AM16: 0 | AN16: 0 | AO16: 0 | AP16: 0 | AQ16: 0 | AR16: 0 | AS16: 0 | AT16: 0
A17: TA 2.3 – Definiendo el patrón MVC++ y la convención de nombres de vistas y controladores | B17: Alexander Hanke | C17: Incremento 1 | D17: =Planificación!H14 | E17: 4 | F17: 4 | G17: 4 | H17: 2 | I17: 0 | J17: 0 | K17: 0 | L17: 0 | M17: 0 | N17: 0 | O17: 0 | P17: 0 | Q17: 0 | R17: 0 | S17: 0 | T17: 0 | U17: 0 | V17: 0 | W17: 0 | X17: 0 | Y17: 0 | Z17: 0 | AA17: 0 | AB17: 0 | AC17: 0 | AD17: 0 | AE17: 0 | AF17: 0 | AG17: 0 | AH17: 0 | AI17: 0 | AJ17: 0 | AK17: 0 | AL17: 0 | AM17: 0 | AN17: 0 | AO17: 0 | AP17: 0 | AQ17: 0 | AR17: 0 | AS17: 0 | AT17: 0
A18: TA 2.4 – Integrando Bootstrap 5 y la plantilla base del sistema | B18: Josué Barrera | C18: Incremento 1 | D18: =Planificación!H15 | E18: 6 | F18: 6 | G18: 6 | H18: 4 | I18: 2 | J18: 0 | K18: 0 | L18: 0 | M18: 0 | N18: 0 | O18: 0 | P18: 0 | Q18: 0 | R18: 0 | S18: 0 | T18: 0 | U18: 0 | V18: 0 | W18: 0 | X18: 0 | Y18: 0 | Z18: 0 | AA18: 0 | AB18: 0 | AC18: 0 | AD18: 0 | AE18: 0 | AF18: 0 | AG18: 0 | AH18: 0 | AI18: 0 | AJ18: 0 | AK18: 0 | AL18: 0 | AM18: 0 | AN18: 0 | AO18: 0 | AP18: 0 | AQ18: 0 | AR18: 0 | AS18: 0 | AT18: 0
A19: TA 3.1 – Implementando el modelo de usuarios con roles del sistema | B19: Alexander Hanke | C19: Incremento 1 | D19: =Planificación!H17 | E19: 6 | F19: 6 | G19: 6 | H19: 6 | I19: 4 | J19: 2 | K19: 0 | L19: 0 | M19: 0 | N19: 0 | O19: 0 | P19: 0 | Q19: 0 | R19: 0 | S19: 0 | T19: 0 | U19: 0 | V19: 0 | W19: 0 | X19: 0 | Y19: 0 | Z19: 0 | AA19: 0 | AB19: 0 | AC19: 0 | AD19: 0 | AE19: 0 | AF19: 0 | AG19: 0 | AH19: 0 | AI19: 0 | AJ19: 0 | AK19: 0 | AL19: 0 | AM19: 0 | AN19: 0 | AO19: 0 | AP19: 0 | AQ19: 0 | AR19: 0 | AS19: 0 | AT19: 0
A20: TA 3.2 – Implementando el inicio y el cierre de sesión | B20: Josué Barrera | C20: Incremento 1 | D20: =Planificación!H18 | E20: 6 | F20: 6 | G20: 6 | H20: 6 | I20: 6 | J20: 4 | K20: 2 | L20: 0 | M20: 0 | N20: 0 | O20: 0 | P20: 0 | Q20: 0 | R20: 0 | S20: 0 | T20: 0 | U20: 0 | V20: 0 | W20: 0 | X20: 0 | Y20: 0 | Z20: 0 | AA20: 0 | AB20: 0 | AC20: 0 | AD20: 0 | AE20: 0 | AF20: 0 | AG20: 0 | AH20: 0 | AI20: 0 | AJ20: 0 | AK20: 0 | AL20: 0 | AM20: 0 | AN20: 0 | AO20: 0 | AP20: 0 | AQ20: 0 | AR20: 0 | AS20: 0 | AT20: 0
A21: TA 3.3 – Implementando la creación y la edición de cuentas de usuario | B21: Alexander Hanke | C21: Incremento 1 | D21: =Planificación!H19 | E21: 6 | F21: 6 | G21: 6 | H21: 6 | I21: 6 | J21: 6 | K21: 4 | L21: 2 | M21: 0 | N21: 0 | O21: 0 | P21: 0 | Q21: 0 | R21: 0 | S21: 0 | T21: 0 | U21: 0 | V21: 0 | W21: 0 | X21: 0 | Y21: 0 | Z21: 0 | AA21: 0 | AB21: 0 | AC21: 0 | AD21: 0 | AE21: 0 | AF21: 0 | AG21: 0 | AH21: 0 | AI21: 0 | AJ21: 0 | AK21: 0 | AL21: 0 | AM21: 0 | AN21: 0 | AO21: 0 | AP21: 0 | AQ21: 0 | AR21: 0 | AS21: 0 | AT21: 0
A22: TA 3.4 – Implementando la deshabilitación de cuentas y el control de acceso por rol | B22: Josué Barrera | C22: Incremento 1 | D22: =Planificación!H20 | E22: 6 | F22: 6 | G22: 6 | H22: 6 | I22: 6 | J22: 6 | K22: 6 | L22: 4 | M22: 2 | N22: 0 | O22: 0 | P22: 0 | Q22: 0 | R22: 0 | S22: 0 | T22: 0 | U22: 0 | V22: 0 | W22: 0 | X22: 0 | Y22: 0 | Z22: 0 | AA22: 0 | AB22: 0 | AC22: 0 | AD22: 0 | AE22: 0 | AF22: 0 | AG22: 0 | AH22: 0 | AI22: 0 | AJ22: 0 | AK22: 0 | AL22: 0 | AM22: 0 | AN22: 0 | AO22: 0 | AP22: 0 | AQ22: 0 | AR22: 0 | AS22: 0 | AT22: 0
A23: TA 3.5 – Implementando el registro y la edición de proveedores | B23: Alexander Hanke | C23: Incremento 1 | D23: =Planificación!H21 | E23: 6 | F23: 6 | G23: 6 | H23: 6 | I23: 6 | J23: 6 | K23: 6 | L23: 6 | M23: 4 | N23: 2 | O23: 0 | P23: 0 | Q23: 0 | R23: 0 | S23: 0 | T23: 0 | U23: 0 | V23: 0 | W23: 0 | X23: 0 | Y23: 0 | Z23: 0 | AA23: 0 | AB23: 0 | AC23: 0 | AD23: 0 | AE23: 0 | AF23: 0 | AG23: 0 | AH23: 0 | AI23: 0 | AJ23: 0 | AK23: 0 | AL23: 0 | AM23: 0 | AN23: 0 | AO23: 0 | AP23: 0 | AQ23: 0 | AR23: 0 | AS23: 0 | AT23: 0
A24: TA 3.6 – Implementando la asignación del jefe de proyecto | B24: Josué Barrera | C24: Incremento 1 | D24: =Planificación!H22 | E24: 6 | F24: 6 | G24: 6 | H24: 6 | I24: 6 | J24: 6 | K24: 6 | L24: 6 | M24: 6 | N24: 4 | O24: 2 | P24: 0 | Q24: 0 | R24: 0 | S24: 0 | T24: 0 | U24: 0 | V24: 0 | W24: 0 | X24: 0 | Y24: 0 | Z24: 0 | AA24: 0 | AB24: 0 | AC24: 0 | AD24: 0 | AE24: 0 | AF24: 0 | AG24: 0 | AH24: 0 | AI24: 0 | AJ24: 0 | AK24: 0 | AL24: 0 | AM24: 0 | AN24: 0 | AO24: 0 | AP24: 0 | AQ24: 0 | AR24: 0 | AS24: 0 | AT24: 0
A25: TA 3.7 – Implementando el cambio de estado del proyecto | B25: Alexander Hanke | C25: Incremento 1 | D25: =Planificación!H23 | E25: 6 | F25: 6 | G25: 6 | H25: 6 | I25: 6 | J25: 6 | K25: 6 | L25: 6 | M25: 6 | N25: 6 | O25: 4 | P25: 2 | Q25: 0 | R25: 0 | S25: 0 | T25: 0 | U25: 0 | V25: 0 | W25: 0 | X25: 0 | Y25: 0 | Z25: 0 | AA25: 0 | AB25: 0 | AC25: 0 | AD25: 0 | AE25: 0 | AF25: 0 | AG25: 0 | AH25: 0 | AI25: 0 | AJ25: 0 | AK25: 0 | AL25: 0 | AM25: 0 | AN25: 0 | AO25: 0 | AP25: 0 | AQ25: 0 | AR25: 0 | AS25: 0 | AT25: 0
A26: TA 3.8 – Implementando la creación de la solicitud de materiales | B26: Josué Barrera | C26: Incremento 1 | D26: =Planificación!H24 | E26: 6 | F26: 6 | G26: 6 | H26: 6 | I26: 6 | J26: 6 | K26: 6 | L26: 6 | M26: 6 | N26: 6 | O26: 6 | P26: 4 | Q26: 2 | R26: 0 | S26: 0 | T26: 0 | U26: 0 | V26: 0 | W26: 0 | X26: 0 | Y26: 0 | Z26: 0 | AA26: 0 | AB26: 0 | AC26: 0 | AD26: 0 | AE26: 0 | AF26: 0 | AG26: 0 | AH26: 0 | AI26: 0 | AJ26: 0 | AK26: 0 | AL26: 0 | AM26: 0 | AN26: 0 | AO26: 0 | AP26: 0 | AQ26: 0 | AR26: 0 | AS26: 0 | AT26: 0
A27: TA 3.9 – Implementando el detalle y la edición de la solicitud de materiales | B27: Alexander Hanke | C27: Incremento 1 | D27: =Planificación!H25 | E27: 6 | F27: 6 | G27: 6 | H27: 6 | I27: 6 | J27: 6 | K27: 6 | L27: 6 | M27: 6 | N27: 6 | O27: 6 | P27: 6 | Q27: 4 | R27: 2 | S27: 0 | T27: 0 | U27: 0 | V27: 0 | W27: 0 | X27: 0 | Y27: 0 | Z27: 0 | AA27: 0 | AB27: 0 | AC27: 0 | AD27: 0 | AE27: 0 | AF27: 0 | AG27: 0 | AH27: 0 | AI27: 0 | AJ27: 0 | AK27: 0 | AL27: 0 | AM27: 0 | AN27: 0 | AO27: 0 | AP27: 0 | AQ27: 0 | AR27: 0 | AS27: 0 | AT27: 0
A28: TA 3.10 – Implementando la consulta y el seguimiento de solicitudes | B28: Josué Barrera | C28: Incremento 1 | D28: =Planificación!H26 | E28: 6 | F28: 6 | G28: 6 | H28: 6 | I28: 6 | J28: 6 | K28: 6 | L28: 6 | M28: 6 | N28: 6 | O28: 6 | P28: 6 | Q28: 6 | R28: 4 | S28: 2 | T28: 0 | U28: 0 | V28: 0 | W28: 0 | X28: 0 | Y28: 0 | Z28: 0 | AA28: 0 | AB28: 0 | AC28: 0 | AD28: 0 | AE28: 0 | AF28: 0 | AG28: 0 | AH28: 0 | AI28: 0 | AJ28: 0 | AK28: 0 | AL28: 0 | AM28: 0 | AN28: 0 | AO28: 0 | AP28: 0 | AQ28: 0 | AR28: 0 | AS28: 0 | AT28: 0
A29: TA 3.11 – Implementando el panel principal con el menú según el rol | B29: Alexander Hanke | C29: Incremento 1 | D29: =Planificación!H27 | E29: 6 | F29: 6 | G29: 6 | H29: 6 | I29: 6 | J29: 6 | K29: 6 | L29: 6 | M29: 6 | N29: 6 | O29: 6 | P29: 6 | Q29: 6 | R29: 6 | S29: 4 | T29: 2 | U29: 0 | V29: 0 | W29: 0 | X29: 0 | Y29: 0 | Z29: 0 | AA29: 0 | AB29: 0 | AC29: 0 | AD29: 0 | AE29: 0 | AF29: 0 | AG29: 0 | AH29: 0 | AI29: 0 | AJ29: 0 | AK29: 0 | AL29: 0 | AM29: 0 | AN29: 0 | AO29: 0 | AP29: 0 | AQ29: 0 | AR29: 0 | AS29: 0 | AT29: 0
A30: TA 3.12 – Cargando los datos de prueba iniciales en la base de datos | B30: Josué Barrera | C30: Incremento 1 | D30: =Planificación!H28 | E30: 4 | F30: 4 | G30: 4 | H30: 4 | I30: 4 | J30: 4 | K30: 4 | L30: 4 | M30: 4 | N30: 4 | O30: 4 | P30: 4 | Q30: 4 | R30: 4 | S30: 4 | T30: 2 | U30: 0 | V30: 0 | W30: 0 | X30: 0 | Y30: 0 | Z30: 0 | AA30: 0 | AB30: 0 | AC30: 0 | AD30: 0 | AE30: 0 | AF30: 0 | AG30: 0 | AH30: 0 | AI30: 0 | AJ30: 0 | AK30: 0 | AL30: 0 | AM30: 0 | AN30: 0 | AO30: 0 | AP30: 0 | AQ30: 0 | AR30: 0 | AS30: 0 | AT30: 0
A31: TA 4.1 – Realizando el modelo entidad-relación del incremento | B31: Roberto Seguel | C31: Incremento 1 | D31: =Planificación!H30 | E31: 6 | F31: 6 | G31: 6 | H31: 6 | I31: 6 | J31: 4 | K31: 2 | L31: 0 | M31: 0 | N31: 0 | O31: 0 | P31: 0 | Q31: 0 | R31: 0 | S31: 0 | T31: 0 | U31: 0 | V31: 0 | W31: 0 | X31: 0 | Y31: 0 | Z31: 0 | AA31: 0 | AB31: 0 | AC31: 0 | AD31: 0 | AE31: 0 | AF31: 0 | AG31: 0 | AH31: 0 | AI31: 0 | AJ31: 0 | AK31: 0 | AL31: 0 | AM31: 0 | AN31: 0 | AO31: 0 | AP31: 0 | AQ31: 0 | AR31: 0 | AS31: 0 | AT31: 0
A32: TA 4.2 – Realizando el diagrama de casos de uso del sistema | B32: Roberto Seguel | C32: Incremento 1 | D32: =Planificación!H31 | E32: 4 | F32: 4 | G32: 4 | H32: 4 | I32: 4 | J32: 4 | K32: 4 | L32: 2 | M32: 0 | N32: 0 | O32: 0 | P32: 0 | Q32: 0 | R32: 0 | S32: 0 | T32: 0 | U32: 0 | V32: 0 | W32: 0 | X32: 0 | Y32: 0 | Z32: 0 | AA32: 0 | AB32: 0 | AC32: 0 | AD32: 0 | AE32: 0 | AF32: 0 | AG32: 0 | AH32: 0 | AI32: 0 | AJ32: 0 | AK32: 0 | AL32: 0 | AM32: 0 | AN32: 0 | AO32: 0 | AP32: 0 | AQ32: 0 | AR32: 0 | AS32: 0 | AT32: 0
A33: TA 4.3 – Realizando los diagramas de secuencia del incremento | B33: Roberto Seguel | C33: Incremento 1 | D33: =Planificación!H32 | E33: 8 | F33: 8 | G33: 8 | H33: 8 | I33: 8 | J33: 8 | K33: 8 | L33: 8 | M33: 8 | N33: 6 | O33: 5 | P33: 3 | Q33: 2 | R33: 0 | S33: 0 | T33: 0 | U33: 0 | V33: 0 | W33: 0 | X33: 0 | Y33: 0 | Z33: 0 | AA33: 0 | AB33: 0 | AC33: 0 | AD33: 0 | AE33: 0 | AF33: 0 | AG33: 0 | AH33: 0 | AI33: 0 | AJ33: 0 | AK33: 0 | AL33: 0 | AM33: 0 | AN33: 0 | AO33: 0 | AP33: 0 | AQ33: 0 | AR33: 0 | AS33: 0 | AT33: 0
A34: TA 4.4 – Realizando el diagrama de despliegue inicial | B34: Roberto Seguel | C34: Incremento 1 | D34: =Planificación!H33 | E34: 4 | F34: 4 | G34: 4 | H34: 4 | I34: 4 | J34: 4 | K34: 4 | L34: 4 | M34: 4 | N34: 4 | O34: 4 | P34: 4 | Q34: 4 | R34: 2 | S34: 0 | T34: 0 | U34: 0 | V34: 0 | W34: 0 | X34: 0 | Y34: 0 | Z34: 0 | AA34: 0 | AB34: 0 | AC34: 0 | AD34: 0 | AE34: 0 | AF34: 0 | AG34: 0 | AH34: 0 | AI34: 0 | AJ34: 0 | AK34: 0 | AL34: 0 | AM34: 0 | AN34: 0 | AO34: 0 | AP34: 0 | AQ34: 0 | AR34: 0 | AS34: 0 | AT34: 0
A35: TA 4.5 – Redactando el informe del Incremento 1 | B35: Roberto Seguel | C35: Incremento 1 | D35: =Planificación!H34 | E35: 8 | F35: 8 | G35: 8 | H35: 8 | I35: 8 | J35: 8 | K35: 8 | L35: 8 | M35: 8 | N35: 8 | O35: 8 | P35: 8 | Q35: 8 | R35: 8 | S35: 6 | T35: 5 | U35: 3 | V35: 2 | W35: 0 | X35: 0 | Y35: 0 | Z35: 0 | AA35: 0 | AB35: 0 | AC35: 0 | AD35: 0 | AE35: 0 | AF35: 0 | AG35: 0 | AH35: 0 | AI35: 0 | AJ35: 0 | AK35: 0 | AL35: 0 | AM35: 0 | AN35: 0 | AO35: 0 | AP35: 0 | AQ35: 0 | AR35: 0 | AS35: 0 | AT35: 0
A36: TA 4.6 – Construyendo la tabla de esfuerzo y las gráficas del sprint | B36: Roberto Seguel | C36: Incremento 1 | D36: =Planificación!H35 | E36: 4 | F36: 4 | G36: 4 | H36: 4 | I36: 4 | J36: 4 | K36: 4 | L36: 4 | M36: 4 | N36: 4 | O36: 4 | P36: 4 | Q36: 4 | R36: 4 | S36: 4 | T36: 4 | U36: 4 | V36: 2 | W36: 0 | X36: 0 | Y36: 0 | Z36: 0 | AA36: 0 | AB36: 0 | AC36: 0 | AD36: 0 | AE36: 0 | AF36: 0 | AG36: 0 | AH36: 0 | AI36: 0 | AJ36: 0 | AK36: 0 | AL36: 0 | AM36: 0 | AN36: 0 | AO36: 0 | AP36: 0 | AQ36: 0 | AR36: 0 | AS36: 0 | AT36: 0
A37: TA 5.1 – Ejecutando las pruebas de caja negra de los casos de uso del incremento | B37: Josué Barrera | C37: Incremento 1 | D37: =Planificación!H37 | E37: 6 | F37: 6 | G37: 6 | H37: 6 | I37: 6 | J37: 6 | K37: 6 | L37: 6 | M37: 6 | N37: 6 | O37: 6 | P37: 6 | Q37: 6 | R37: 6 | S37: 6 | T37: 6 | U37: 4 | V37: 2 | W37: 0 | X37: 0 | Y37: 0 | Z37: 0 | AA37: 0 | AB37: 0 | AC37: 0 | AD37: 0 | AE37: 0 | AF37: 0 | AG37: 0 | AH37: 0 | AI37: 0 | AJ37: 0 | AK37: 0 | AL37: 0 | AM37: 0 | AN37: 0 | AO37: 0 | AP37: 0 | AQ37: 0 | AR37: 0 | AS37: 0 | AT37: 0
A38: TA 5.2 – Documentando los casos de prueba y su evidencia | B38: Roberto Seguel | C38: Incremento 1 | D38: =Planificación!H38 | E38: 4 | F38: 4 | G38: 4 | H38: 4 | I38: 4 | J38: 4 | K38: 4 | L38: 4 | M38: 4 | N38: 4 | O38: 4 | P38: 4 | Q38: 4 | R38: 4 | S38: 4 | T38: 4 | U38: 4 | V38: 3 | W38: 1 | X38: 0 | Y38: 0 | Z38: 0 | AA38: 0 | AB38: 0 | AC38: 0 | AD38: 0 | AE38: 0 | AF38: 0 | AG38: 0 | AH38: 0 | AI38: 0 | AJ38: 0 | AK38: 0 | AL38: 0 | AM38: 0 | AN38: 0 | AO38: 0 | AP38: 0 | AQ38: 0 | AR38: 0 | AS38: 0 | AT38: 0
A39: TA 5.3 – Corrigiendo los hallazgos levantados en las pruebas | B39: Josué Barrera | C39: Incremento 1 | D39: =Planificación!H39 | E39: 4 | F39: 4 | G39: 4 | H39: 4 | I39: 4 | J39: 4 | K39: 4 | L39: 4 | M39: 4 | N39: 4 | O39: 4 | P39: 4 | Q39: 4 | R39: 4 | S39: 4 | T39: 4 | U39: 4 | V39: 4 | W39: 3 | X39: 1 | Y39: 0 | Z39: 0 | AA39: 0 | AB39: 0 | AC39: 0 | AD39: 0 | AE39: 0 | AF39: 0 | AG39: 0 | AH39: 0 | AI39: 0 | AJ39: 0 | AK39: 0 | AL39: 0 | AM39: 0 | AN39: 0 | AO39: 0 | AP39: 0 | AQ39: 0 | AR39: 0 | AS39: 0 | AT39: 0
A40: SPRINT 2 · INCREMENTO 2 (52 tareas)
A41: TA 1.1 – Montando la máquina virtual Ubuntu Server en el servidor HP ProLiant DL20 | B41: Matías Medina | C41: Incremento 2 | D41: =Planificación!H43 | E41: 6 | F41: 6 | G41: 6 | H41: 6 | I41: 6 | J41: 6 | K41: 6 | L41: 6 | M41: 6 | N41: 6 | O41: 6 | P41: 6 | Q41: 6 | R41: 6 | S41: 6 | T41: 6 | U41: 6 | V41: 6 | W41: 6 | X41: 6 | Y41: 6 | Z41: 3 | AA41: 0 | AB41: 0 | AC41: 0 | AD41: 0 | AE41: 0 | AF41: 0 | AG41: 0 | AH41: 0 | AI41: 0 | AJ41: 0 | AK41: 0 | AL41: 0 | AM41: 0 | AN41: 0 | AO41: 0 | AP41: 0 | AQ41: 0 | AR41: 0 | AS41: 0 | AT41: 0
...

Sheet Gráficas acumuladas
A1: Gráficas de seguimiento acumuladas — Incrementos 1, 2 y 3
A2: 61 días de sprint: 21 del Sprint 1, 21 del Sprint 2 y 19 del Sprint 3. El esfuerzo pendiente parte del total de los tres incrementos y no se reinicia al cambiar de sprint. La línea planificada se calcula por tramo con las horas estimadas de cada incremento, y la real con las horas efectivas.
A4: Día | B4: Fecha | C4: Sprint | D4: Pendiente real (HH) | E4: Pendiente planificado (HH) | F4: Acumulado real (HH) | G4: Acumulado planificado (HH) | H4: Alcance comprometido (HH)
A5: 0 | B5: Inicio | C5: Sprint 1 | D5: ='Tabla de Esfuerzo'!$D$93+'Tabla de Esfuerzo'!$E$9 | E5: =Planificación!$E$133 | F5: =$D$5-D5 | G5: =Planificación!$E$133-E5 | H5: =Planificación!$H$40
A6: 1 | B6: 27-07 | C6: Sprint 1 | D6: ='Tabla de Esfuerzo'!E6 | E6: =ROUND(Planificación!$E$133-Planificación!$E$40*A6/21,0) | F6: =$D$5-D6 | G6: =Planificación!$E$133-E6 | H6: =Planificación!$H$40
A7: 2 | B7: 28-07 | C7: Sprint 1 | D7: ='Tabla de Esfuerzo'!F6 | E7: =ROUND(Planificación!$E$133-Planificación!$E$40*A7/21,0) | F7: =$D$5-D7 | G7: =Planificación!$E$133-E7 | H7: =Planificación!$H$40
A8: 3 | B8: 29-07 | C8: Sprint 1 | D8: ='Tabla de Esfuerzo'!G6 | E8: =ROUND(Planificación!$E$133-Planificación!$E$40*A8/21,0) | F8: =$D$5-D8 | G8: =Planificación!$E$133-E8 | H8: =Planificación!$H$40
A9: 4 | B9: 30-07 | C9: Sprint 1 | D9: ='Tabla de Esfuerzo'!H6 | E9: =ROUND(Planificación!$E$133-Planificación!$E$40*A9/21,0) | F9: =$D$5-D9 | G9: =Planificación!$E$133-E9 | H9: =Planificación!$H$40
A10: 5 | B10: 31-07 | C10: Sprint 1 | D10: ='Tabla de Esfuerzo'!I6 | E10: =ROUND(Planificación!$E$133-Planificación!$E$40*A10/21,0) | F10: =$D$5-D10 | G10: =Planificación!$E$133-E10 | H10: =Planificación!$H$40
A11: 6 | B11: 01-08 | C11: Sprint 1 | D11: ='Tabla de Esfuerzo'!J6 | E11: =ROUND(Planificación!$E$133-Planificación!$E$40*A11/21,0) | F11: =$D$5-D11 | G11: =Planificación!$E$133-E11 | H11: =Planificación!$H$40
A12: 7 | B12: 02-08 | C12: Sprint 1 | D12: ='Tabla de Esfuerzo'!K6 | E12: =ROUND(Planificación!$E$133-Planificación!$E$40*A12/21,0) | F12: =$D$5-D12 | G12: =Planificación!$E$133-E12 | H12: =Planificación!$H$40
A13: 8 | B13: 03-08 | C13: Sprint 1 | D13: ='Tabla de Esfuerzo'!L6 | E13: =ROUND(Planificación!$E$133-Planificación!$E$40*A13/21,0) | F13: =$D$5-D13 | G13: =Planificación!$E$133-E13 | H13: =Planificación!$H$40
A14: 9 | B14: 04-08 | C14: Sprint 1 | D14: ='Tabla de Esfuerzo'!M6 | E14: =ROUND(Planificación!$E$133-Planificación!$E$40*A14/21,0) | F14: =$D$5-D14 | G14: =Planificación!$E$133-E14 | H14: =Planificación!$H$40
A15: 10 | B15: 05-08 | C15: Sprint 1 | D15: ='Tabla de Esfuerzo'!N6 | E15: =ROUND(Planificación!$E$133-Planificación!$E$40*A15/21,0) | F15: =$D$5-D15 | G15: =Planificación!$E$133-E15 | H15: =Planificación!$H$40
A16: 11 | B16: 06-08 | C16: Sprint 1 | D16: ='Tabla de Esfuerzo'!O6 | E16: =ROUND(Planificación!$E$133-Planificación!$E$40*A16/21,0) | F16: =$D$5-D16 | G16: =Planificación!$E$133-E16 | H16: =Planificación!$H$40
A17: 12 | B17: 07-08 | C17: Sprint 1 | D17: ='Tabla de Esfuerzo'!P6 | E17: =ROUND(Planificación!$E$133-Planificación!$E$40*A17/21,0) | F17: =$D$5-D17 | G17: =Planificación!$E$133-E17 | H17: =Planificación!$H$40
A18: 13 | B18: 08-08 | C18: Sprint 1 | D18: ='Tabla de Esfuerzo'!Q6 | E18: =ROUND(Planificación!$E$133-Planificación!$E$40*A18/21,0) | F18: =$D$5-D18 | G18: =Planificación!$E$133-E18 | H18: =Planificación!$H$40
A19: 14 | B19: 09-08 | C19: Sprint 1 | D19: ='Tabla de Esfuerzo'!R6 | E19: =ROUND(Planificación!$E$133-Planificación!$E$40*A19/21,0) | F19: =$D$5-D19 | G19: =Planificación!$E$133-E19 | H19: =Planificación!$H$40
A20: 15 | B20: 10-08 | C20: Sprint 1 | D20: ='Tabla de Esfuerzo'!S6 | E20: =ROUND(Planificación!$E$133-Planificación!$E$40*A20/21,0) | F20: =$D$5-D20 | G20: =Planificación!$E$133-E20 | H20: =Planificación!$H$40
A21: 16 | B21: 11-08 | C21: Sprint 1 | D21: ='Tabla de Esfuerzo'!T6 | E21: =ROUND(Planificación!$E$133-Planificación!$E$40*A21/21,0) | F21: =$D$5-D21 | G21: =Planificación!$E$133-E21 | H21: =Planificación!$H$40
A22: 17 | B22: 12-08 | C22: Sprint 1 | D22: ='Tabla de Esfuerzo'!U6 | E22: =ROUND(Planificación!$E$133-Planificación!$E$40*A22/21,0) | F22: =$D$5-D22 | G22: =Planificación!$E$133-E22 | H22: =Planificación!$H$40
A23: 18 | B23: 13-08 | C23: Sprint 1 | D23: ='Tabla de Esfuerzo'!V6 | E23: =ROUND(Planificación!$E$133-Planificación!$E$40*A23/21,0) | F23: =$D$5-D23 | G23: =Planificación!$E$133-E23 | H23: =Planificación!$H$40
A24: 19 | B24: 14-08 | C24: Sprint 1 | D24: ='Tabla de Esfuerzo'!W6 | E24: =ROUND(Planificación!$E$133-Planificación!$E$40*A24/21,0) | F24: =$D$5-D24 | G24: =Planificación!$E$133-E24 | H24: =Planificación!$H$40
A25: 20 | B25: 15-08 | C25: Sprint 1 | D25: ='Tabla de Esfuerzo'!X6 | E25: =ROUND(Planificación!$E$133-Planificación!$E$40*A25/21,0) | F25: =$D$5-D25 | G25: =Planificación!$E$133-E25 | H25: =Planificación!$H$40
A26: 21 | B26: 16-08 | C26: Sprint 1 | D26: ='Tabla de Esfuerzo'!Y6 | E26: =ROUND(Planificación!$E$133-Planificación!$E$40*A26/21,0) | F26: =$D$5-D26 | G26: =Planificación!$E$133-E26 | H26: =Planificación!$H$40
A27: 22 | B27: 24-08 | C27: Sprint 2 | D27: ='Tabla de Esfuerzo'!Z6 | E27: =ROUND(Planificación!$E$133-Planificación!$E$40-Planificación!$E$95*(A27-21)/21,0) | F27: =$D$5-D27 | G27: =Planificación!$E$133-E27 | H27: ='Tabla de Esfuerzo'!$D$93
A28: 23 | B28: 25-08 | C28: Sprint 2 | D28: ='Tabla de Esfuerzo'!AA6 | E28: =ROUND(Planificación!$E$133-Planificación!$E$40-Planificación!$E$95*(A28-21)/21,0) | F28: =$D$5-D28 | G28: =Planificación!$E$133-E28 | H28: ='Tabla de Esfuerzo'!$D$93
A29: 24 | B29: 26-08 | C29: Sprint 2 | D29: ='Tabla de Esfuerzo'!AB6 | E29: =ROUND(Planificación!$E$133-Planificación!$E$40-Planificación!$E$95*(A29-21)/21,0) | F29: =$D$5-D29 | G29: =Planificación!$E$133-E29 | H29: ='Tabla de Esfuerzo'!$D$93
A30: 25 | B30: 27-08 | C30: Sprint 2 | D30: ='Tabla de Esfuerzo'!AC6 | E30: =ROUND(Planificación!$E$133-Planificación!$E$40-Planificación!$E$95*(A30-21)/21,0) | F30: =$D$5-D30 | G30: =Planificación!$E$133-E30 | H30: ='Tabla de Esfuerzo'!$D$93
A31: 26 | B31: 28-08 | C31: Sprint 2 | D31: ='Tabla de Esfuerzo'!AD6 | E31: =ROUND(Planificación!$E$133-Planificación!$E$40-Planificación!$E$95*(A31-21)/21,0) | F31: =$D$5-D31 | G31: =Planificación!$E$133-E31 | H31: ='Tabla de Esfuerzo'!$D$93
A32: 27 | B32: 29-08 | C32: Sprint 2 | D32: ='Tabla de Esfuerzo'!AE6 | E32: =ROUND(Planificación!$E$133-Planificación!$E$40-Planificación!$E$95*(A32-21)/21,0) | F32: =$D$5-D32 | G32: =Planificación!$E$133-E32 | H32: ='Tabla de Esfuerzo'!$D$93
A33: 28 | B33: 30-08 | C33: Sprint 2 | D33: ='Tabla de Esfuerzo'!AF6 | E33: =ROUND(Planificación!$E$133-Planificación!$E$40-Planificación!$E$95*(A33-21)/21,0) | F33: =$D$5-D33 | G33: =Planificación!$E$133-E33 | H33: ='Tabla de Esfuerzo'!$D$93
A34: 29 | B34: 31-08 | C34: Sprint 2 | D34: ='Tabla de Esfuerzo'!AG6 | E34: =ROUND(Planificación!$E$133-Planificación!$E$40-Planificación!$E$95*(A34-21)/21,0) | F34: =$D$5-D34 | G34: =Planificación!$E$133-E34 | H34: ='Tabla de Esfuerzo'!$D$93
A35: 30 | B35: 01-09 | C35: Sprint 2 | D35: ='Tabla de Esfuerzo'!AH6 | E35: =ROUND(Planificación!$E$133-Planificación!$E$40-Planificación!$E$95*(A35-21)/21,0) | F35: =$D$5-D35 | G35: =Planificación!$E$133-E35 | H35: ='Tabla de Esfuerzo'!$D$93
A36: 31 | B36: 02-09 | C36: Sprint 2 | D36: ='Tabla de Esfuerzo'!AI6 | E36: =ROUND(Planificación!$E$133-Planificación!$E$40-Planificación!$E$95*(A36-21)/21,0) | F36: =$D$5-D36 | G36: =Planificación!$E$133-E36 | H36: ='Tabla de Esfuerzo'!$D$93
A37: 32 | B37: 03-09 | C37: Sprint 2 | D37: ='Tabla de Esfuerzo'!AJ6 | E37: =ROUND(Planificación!$E$133-Planificación!$E$40-Planificación!$E$95*(A37-21)/21,0) | F37: =$D$5-D37 | G37: =Planificación!$E$133-E37 | H37: ='Tabla de Esfuerzo'!$D$93
A38: 33 | B38: 04-09 | C38: Sprint 2 | D38: ='Tabla de Esfuerzo'!AK6 | E38: =ROUND(Planificación!$E$133-Planificación!$E$40-Planificación!$E$95*(A38-21)/21,0) | F38: =$D$5-D38 | G38: =Planificación!$E$133-E38 | H38: ='Tabla de Esfuerzo'!$D$93
A39: 34 | B39: 05-09 | C39: Sprint 2 | D39: ='Tabla de Esfuerzo'!AL6 | E39: =ROUND(Planificación!$E$133-Planificación!$E$40-Planificación!$E$95*(A39-21)/21,0) | F39: =$D$5-D39 | G39: =Planificación!$E$133-E39 | H39: ='Tabla de Esfuerzo'!$D$93
A40: 35 | B40: 06-09 | C40: Sprint 2 | D40: ='Tabla de Esfuerzo'!AM6 | E40: =ROUND(Planificación!$E$133-Planificación!$E$40-Planificación!$E$95*(A40-21)/21,0) | F40: =$D$5-D40 | G40: =Planificación!$E$133-E40 | H40: ='Tabla de Esfuerzo'!$D$93
A41: 36 | B41: 07-09 | C41: Sprint 2 | D41: ='Tabla de Esfuerzo'!AN6 | E41: =ROUND(Planificación!$E$133-Planificación!$E$40-Planificación!$E$95*(A41-21)/21,0) | F41: =$D$5-D41 | G41: =Planificación!$E$133-E41 | H41: ='Tabla de Esfuerzo'!$D$93
...
